<?xml version="1.0" ?>
<sdf version="1.8">
    <model name='generic_robot' canonical_link='chassis'>

        <frame name="lidar_frame" attached_to='chassis'>
            <pose>0.8 0 0.5 0 0 0</pose>
        </frame>
        
        <!--chassis-->
        <link name="chassis">
        <pose>0 0 0 0 0 1.57</pose>
    
        <!-- Visual Geometry -->
        <visual name="act_visual">
            <geometry>
            <mesh>
                <uri>model://mouse_robot/mouse_robot.stl</uri>
                <scale>0.015 0.015 0.015</scale>
            </mesh>
            </geometry>
            <material>
                <ambient>1 1 1 1</ambient>  
                <diffuse>1 1 1 1</diffuse>  
                <specular>0.8 0.8 0.8 1</specular> 
            </material>
        </visual>

        <!-- Collision Geometry -->
        <collision name="chassis_collision">
            <geometry>
            <box>
                <size>0.4 0.2 0.1</size>
            </box>
            </geometry>
        </collision>

        <!-- Inertial Properties -->
        <inertial>
            <mass>1.5</mass>
            <inertia>
            <ixx>0.095</ixx>
            <iyy>0.381</iyy>
            <izz>0.476</izz>
            </inertia>
        </inertial>

        <sensor type="gpu_lidar" name="lidar">
            <pose relative_to='lidar_frame'>0 0 0 0 0 0</pose>
            <topic>lidar</topic>
            <update_rate>10</update_rate>
            <ray>
                <scan>
                    <horizontal>
                        <samples>640</samples>
                        <resolution>1</resolution>
                        <min_angle>-1.396263</min_angle>
                        <max_angle>1.396263</max_angle>
                    </horizontal>
                    <vertical>
                        <samples>1</samples>
                        <resolution>0.01</resolution>
                        <min_angle>0</min_angle>
                        <max_angle>0</max_angle>
                    </vertical>
                </scan>
                <range>
                    <min>0.08</min>
                    <max>10.0</max>
                    <resolution>0.01</resolution>
                </range>
            </ray>
            <always_on>1</always_on>
            <visualize>true</visualize>
        </sensor>
        </link>

        <!-- Left wheel-->
        <link name='left_wheel'>
            <pose relative_to="chassis">0.09 0.19 0 -1.5707 0 1.57</pose> 
            <inertial>
                <mass>1</mass>
                <inertia>
                    <ixx>0.043333</ixx>
                    <ixy>0</ixy>
                    <ixz>0</ixz>
                    <iyy>0.043333</iyy>
                    <iyz>0</iyz>
                    <izz>0.08</izz>
                </inertia>
            </inertial>
            <visual name='visual'>
                <geometry>
                    <cylinder>
                        <radius>0.1</radius>
                        <length>0.03</length>
                    </cylinder>
                </geometry>
                <material>
                    <ambient>0 0 0 1</ambient> 
                    <diffuse>0 0 0 1</diffuse>  
                    <specular>0.1 0.1 0.1 1</specular>
                </material>
            </visual>
            <collision name='collision'>
                <geometry>
                    <cylinder>
                        <radius>0.1</radius>
                        <length>0.03</length>
                    </cylinder>
                </geometry>
            </collision>
        </link>

        <!--The same as left wheel but with different position-->
        <link name='right_wheel'>
            <pose relative_to="chassis">-0.09 0.19 0 -1.5707 0 1.57</pose> 
            <inertial>
                <mass>1</mass>
                <inertia>
                    <ixx>0.043333</ixx>
                    <ixy>0</ixy>
                    <ixz>0</ixz>
                    <iyy>0.043333</iyy>
                    <iyz>0</iyz>
                    <izz>0.08</izz>
                </inertia>
            </inertial>
            <visual name='visual'>
                <geometry>
                    <cylinder>
                        <radius>0.1</radius>
                        <length>0.03</length>    
                    </cylinder>
                </geometry>
                <material>
                    <ambient>0 0 0 1</ambient> 
                    <diffuse>0 0 0 1</diffuse>  
                    <specular>0.1 0.1 0.1 1</specular>
                </material>
            </visual>
            <collision name='collision'>
                <geometry>
                    <cylinder>
                        <radius>0.1</radius>
                        <length>0.03</length>
                    </cylinder>
                </geometry>
            </collision>
        </link>

        <frame name="caster_frame" attached_to='chassis'>
            <pose relative_to="chassis">0 0.02 -0.03 0 0 0</pose>
        </frame>

        <link name='caster'>
            <pose relative_to='caster_frame'>0 0 0 0 0 0</pose>
            <inertial>
                <mass>1</mass>
                <inertia>
                    <ixx>0.016</ixx>
                    <ixy>0</ixy>
                    <ixz>0</ixz>
                    <iyy>0.016</iyy>
                    <iyz>0</iyz>
                    <izz>0.016</izz>
                </inertia>
            </inertial>
            <visual name='visual'>
                <geometry>
                    <sphere>
                        <radius>0.04</radius>
                    </sphere>
                </geometry>
                <material>
                    <ambient>0 0 0 1</ambient> 
                    <diffuse>0 0 0 1</diffuse>  
                    <specular>0.1 0.1 0.1 1</specular>
                </material>
            </visual>
            <collision name='collision'>
                <geometry>
                    <sphere>
                        <radius>0.04</radius>
                    </sphere>
                </geometry>
            </collision>
        </link>


        <!--left wheel joint-->
        <joint name='left_wheel_joint' type='revolute'>
            <pose relative_to='left_wheel'/>
            <parent>chassis</parent>
            <child>left_wheel</child>
            <axis>
                <xyz expressed_in='__model__'>0 1 0</xyz> <!--can be descired to any frame or even arbitrary frames-->
                <limit>
                    <lower>-1.79769e+308</lower>    <!--negative infinity-->
                    <upper>1.79769e+308</upper>     <!--positive infinity-->
                </limit>
            </axis>
        </joint>

        <!--right wheel joint-->
        <joint name='right_wheel_joint' type='revolute'>
            <pose relative_to='right_wheel'/>
            <parent>chassis</parent>
            <child>right_wheel</child>
            <axis>
                <xyz expressed_in='__model__'>0 1 0</xyz>
                <limit>
                    <lower>-1.79769e+308</lower>    <!--negative infinity-->
                    <upper>1.79769e+308</upper>     <!--positive infinity-->
                </limit>
            </axis>
        </joint>

        <!--caster wheel joint--> <!--pose defult value is the child-->
        <joint name='caster_wheel' type='ball'>
            <parent>chassis</parent>
            <child>caster</child>
        </joint>

        <plugin
            filename="gz-sim-diff-drive-system"
            name="gz::sim::systems::DiffDrive">
            <left_joint>left_wheel_joint</left_joint>
            <right_joint>right_wheel_joint</right_joint>
            <wheel_separation>0.19</wheel_separation>
            <wheel_radius>0.1</wheel_radius>
            <odom_publish_frequency>10</odom_publish_frequency>
            <topic>cmd_vel</topic>
        </plugin>

        <!-- Moving Based on Key Press (WASD)-->
        <plugin filename="gz-sim-triggered-publisher-system"
                name="gz::sim::systems::TriggeredPublisher">
            <input type="gz.msgs.Int32" topic="/keyboard/keypress">
                <match field="data">87</match>
            </input>
            <output type="gz.msgs.Twist" topic="/cmd_vel">
                linear: {x: 0.5}, angular: {z: 0.0}
            </output>   
        </plugin>
        <plugin filename="gz-sim-triggered-publisher-system"
                name="gz::sim::systems::TriggeredPublisher">
            <input type="gz.msgs.Int32" topic="/keyboard/keypress">
                <match field="data">83</match>
            </input>
            <output type="gz.msgs.Twist" topic="/cmd_vel">
                linear: {x: -0.5}, angular: {z: 0.0}
            </output> 
        </plugin>
        <plugin filename="gz-sim-triggered-publisher-system"
                name="gz::sim::systems::TriggeredPublisher">
            <input type="gz.msgs.Int32" topic="/keyboard/keypress">
                <match field="data">65</match>
            </input>
            <output type="gz.msgs.Twist" topic="/cmd_vel">
                linear: {x: 0.0}, angular: {z: 0.5}
            </output>
        </plugin>
        <plugin filename="gz-sim-triggered-publisher-system"
                name="gz::sim::systems::TriggeredPublisher">
            <input type="gz.msgs.Int32" topic="/keyboard/keypress">
                <match field="data">68</match>
            </input>
            <output type="gz.msgs.Twist" topic="/cmd_vel">
                linear: {x: 0.0}, angular: {z: -0.5}
            </output>
        </plugin>
    </model>
</sdf>